Workbook

Sheet Materials
A1: material_id | B1: category | C1: grade | D1: name | E1: fck_MPa | F1: E_MPa | G1: density_kg_m3 | H1: unit_weight_kN_m3 | I1: design_unit_weight_kN_m3 | J1: poisson_ratio | K1: fy_MPa | L1: fu_MPa | M1: property_type | N1: data_status | O1: auto_apply | P1: standard | Q1: source_id | R1: note
A2: CONC-C18 | B2: Concrete | C2: C18 | D2: Concrete fck=18 MPa | E2: 18 | F2: 23817.334 | G2: 2400 | H2: =G2*Meta!$C$5/1000 -> 23.53596 | J2: 0.18 | M2: FORMULA | N2: VERIFIED | O2: TRUE | P2: KDS 14 20 10 콘크리트구조 해석과 설계 원칙 | Q2: SRC-KDS-CONC | R2: E는 KDS식 계산. 보통중량 콘크리트 가정; 골재/단위질량이 다르면 수정.
A3: CONC-C21 | B3: Concrete | C3: C21 | D3: Concrete fck=21 MPa | E3: 21 | F3: 24854.151 | G3: 2400 | H3: =G3*Meta!$C$5/1000 -> 23.53596 | J3: 0.18 | M3: FORMULA | N3: VERIFIED | O3: TRUE | P3: KDS 14 20 10 콘크리트구조 해석과 설계 원칙 | Q3: SRC-KDS-CONC | R3: E는 KDS식 계산. 보통중량 콘크리트 가정; 골재/단위질량이 다르면 수정.
A4: CONC-C24 | B4: Concrete | C4: C24 | D4: Concrete fck=24 MPa | E4: 24 | F4: 25811.006 | G4: 2400 | H4: =G4*Meta!$C$5/1000 -> 23.53596 | J4: 0.18 | M4: FORMULA | N4: VERIFIED | O4: TRUE | P4: KDS 14 20 10 콘크리트구조 해석과 설계 원칙 | Q4: SRC-KDS-CONC | R4: E는 KDS식 계산. 보통중량 콘크리트 가정; 골재/단위질량이 다르면 수정.
A5: CONC-C27 | B5: Concrete | C5: C27 | D5: Concrete fck=27 MPa | E5: 27 | F5: 26701.736 | G5: 2400 | H5: =G5*Meta!$C$5/1000 -> 23.53596 | J5: 0.18 | M5: FORMULA | N5: VERIFIED | O5: TRUE | P5: KDS 14 20 10 콘크리트구조 해석과 설계 원칙 | Q5: SRC-KDS-CONC | R5: E는 KDS식 계산. 보통중량 콘크리트 가정; 골재/단위질량이 다르면 수정.
A6: CONC-C30 | B6: Concrete | C6: C30 | D6: Concrete fck=30 MPa | E6: 30 | F6: 27536.7 | G6: 2400 | H6: =G6*Meta!$C$5/1000 -> 23.53596 | J6: 0.18 | M6: FORMULA | N6: VERIFIED | O6: TRUE | P6: KDS 14 20 10 콘크리트구조 해석과 설계 원칙 | Q6: SRC-KDS-CONC | R6: E는 KDS식 계산. 보통중량 콘크리트 가정; 골재/단위질량이 다르면 수정.
A7: CONC-C35 | B7: Concrete | C7: C35 | D7: Concrete fck=35 MPa | E7: 35 | F7: 28825.297 | G7: 2400 | H7: =G7*Meta!$C$5/1000 -> 23.53596 | J7: 0.18 | M7: FORMULA | N7: VERIFIED | O7: TRUE | P7: KDS 14 20 10 콘크리트구조 해석과 설계 원칙 | Q7: SRC-KDS-CONC | R7: E는 KDS식 계산. 보통중량 콘크리트 가정; 골재/단위질량이 다르면 수정.
A8: CONC-C40 | B8: Concrete | C8: C40 | D8: Concrete fck=40 MPa | E8: 40 | F8: 30007.961 | G8: 2400 | H8: =G8*Meta!$C$5/1000 -> 23.53596 | J8: 0.18 | M8: FORMULA | N8: VERIFIED | O8: TRUE | P8: KDS 14 20 10 콘크리트구조 해석과 설계 원칙 | Q8: SRC-KDS-CONC | R8: E는 KDS식 계산. 보통중량 콘크리트 가정; 골재/단위질량이 다르면 수정.
A9: CONC-C50 | B9: Concrete | C9: C50 | D9: Concrete fck=50 MPa | E9: 50 | F9: 32519.83 | G9: 2400 | H9: =G9*Meta!$C$5/1000 -> 23.53596 | J9: 0.18 | M9: FORMULA | N9: VERIFIED | O9: TRUE | P9: KDS 14 20 10 콘크리트구조 해석과 설계 원칙 | Q9: SRC-KDS-CONC | R9: E는 KDS식 계산. 보통중량 콘크리트 가정; 골재/단위질량이 다르면 수정.
A10: CONC-C60 | B10: Concrete | C10: C60 | D10: Concrete fck=60 MPa | E10: 60 | F10: 34350.54 | G10: 2400 | H10: =G10*Meta!$C$5/1000 -> 23.53596 | J10: 0.18 | M10: FORMULA | N10: VERIFIED | O10: TRUE | P10: KDS 14 20 10 콘크리트구조 해석과 설계 원칙 | Q10: SRC-KDS-CONC | R10: E는 KDS식 계산. 보통중량 콘크리트 가정; 골재/단위질량이 다르면 수정.
A11: CONC-C70 | B11: Concrete | C11: C70 | D11: Concrete fck=70 MPa | E11: 70 | F11: 36317.599 | G11: 2400 | H11: =G11*Meta!$C$5/1000 -> 23.53596 | J11: 0.18 | M11: FORMULA | N11: VERIFIED | O11: TRUE | P11: KDS 14 20 10 콘크리트구조 해석과 설계 원칙 | Q11: SRC-KDS-CONC | R11: E는 KDS식 계산. 보통중량 콘크리트 가정; 골재/단위질량이 다르면 수정.
A12: CONC-C80 | B12: Concrete | C12: C80 | D12: Concrete fck=80 MPa | E12: 80 | F12: 37807.662 | G12: 2400 | H12: =G12*Meta!$C$5/1000 -> 23.53596 | J12: 0.18 | M12: FORMULA | N12: VERIFIED | O12: TRUE | P12: KDS 14 20 10 콘크리트구조 해석과 설계 원칙 | Q12: SRC-KDS-CONC | R12: E는 KDS식 계산. 보통중량 콘크리트 가정; 골재/단위질량이 다르면 수정.
A13: STL-SS275 | B13: Structural Steel | C13: SS275 | D13: SS275 structural steel | F13: 200000 | G13: 7850 | H13: =G13*Meta!$C$5/1000 -> 76.982202 | J13: 0.3 | M13: CONDITIONAL | N13: PENDING | O13: FALSE | P13: KS D 3503 일반 구조용 압연 강재 | Q13: SRC-KS-D3503 | R13: fy는 두께·제품형태 조건에 따라 PropertyRules 참조; 적용 KS 원문 확인.
A14: STL-SM275 | B14: Structural Steel | C14: SM275 | D14: SM275 structural steel | F14: 200000 | G14: 7850 | H14: =G14*Meta!$C$5/1000 -> 76.982202 | J14: 0.3 | M14: CONSTANT | N14: PENDING | O14: FALSE | P14: KS D 3515 용접 구조용 압연 강재 | Q14: SRC-KS-D3515 | R14: fy는 두께·제품형태 조건에 따라 PropertyRules 참조; 적용 KS 원문 확인.
A15: STL-SM355 | B15: Structural Steel | C15: SM355 | D15: SM355 structural steel | F15: 200000 | G15: 7850 | H15: =G15*Meta!$C$5/1000 -> 76.982202 | J15: 0.3 | M15: CONSTANT | N15: PENDING | O15: FALSE | P15: KS D 3515 용접 구조용 압연 강재 | Q15: SRC-KS-D3515 | R15: fy는 두께·제품형태 조건에 따라 PropertyRules 참조; 적용 KS 원문 확인.
A16: STL-SM420 | B16: Structural Steel | C16: SM420 | D16: SM420 structural steel | F16: 200000 | G16: 7850 | H16: =G16*Meta!$C$5/1000 -> 76.982202 | J16: 0.3 | M16: CONSTANT | N16: PENDING | O16: FALSE | P16: KS D 3515 용접 구조용 압연 강재 | Q16: SRC-KS-D3515 | R16: fy는 두께·제품형태 조건에 따라 PropertyRules 참조; 적용 KS 원문 확인.
A17: STL-SM460 | B17: Structural Steel | C17: SM460 | D17: SM460 structural steel | F17: 200000 | G17: 7850 | H17: =G17*Meta!$C$5/1000 -> 76.982202 | J17: 0.3 | M17: CONSTANT | N17: PENDING | O17: FALSE | P17: KS D 3515 용접 구조용 압연 강재 | Q17: SRC-KS-D3515 | R17: fy는 두께·제품형태 조건에 따라 PropertyRules 참조; 적용 KS 원문 확인.
A18: STL-SN275 | B18: Structural Steel | C18: SN275 | D18: SN275 structural steel | F18: 200000 | G18: 7850 | H18: =G18*Meta!$C$5/1000 -> 76.982202 | J18: 0.3 | M18: CONSTANT | N18: PENDING | O18: FALSE | P18: 건축구조용 압연강재 관련 KS | Q18: SRC-KS-SN | R18: fy는 두께·제품형태 조건에 따라 PropertyRules 참조; 적용 KS 원문 확인.
A19: STL-SN355 | B19: Structural Steel | C19: SN355 | D19: SN355 structural steel | F19: 200000 | G19: 7850 | H19: =G19*Meta!$C$5/1000 -> 76.982202 | J19: 0.3 | M19: CONSTANT | N19: PENDING | O19: FALSE | P19: 건축구조용 압연강재 관련 KS | Q19: SRC-KS-SN | R19: fy는 두께·제품형태 조건에 따라 PropertyRules 참조; 적용 KS 원문 확인.
A20: STL-SN460 | B20: Structural Steel | C20: SN460 | D20: SN460 structural steel | F20: 200000 | G20: 7850 | H20: =G20*Meta!$C$5/1000 -> 76.982202 | J20: 0.3 | M20: CONSTANT | N20: PENDING | O20: FALSE | P20: 건축구조용 압연강재 관련 KS | Q20: SRC-KS-SN | R20: fy는 두께·제품형태 조건에 따라 PropertyRules 참조; 적용 KS 원문 확인.
A21: REBAR-SD300 | B21: Reinforcing Steel | C21: SD300 | D21: SD300 reinforcing bar | F21: 200000 | G21: 7850 | H21: =G21*Meta!$C$5/1000 -> 76.982202 | J21: 0.3 | K21: 300 | M21: CONSTANT | N21: PENDING | O21: FALSE | P21: KS D 3504 철근 콘크리트용 봉강 | Q21: SRC-KS-D3504 | R21: fy는 강종 기호의 공칭 항복강도. fu/연신율은 KS 원문 및 지름 조건 확인.
A22: REBAR-SD400 | B22: Reinforcing Steel | C22: SD400 | D22: SD400 reinforcing bar | F22: 200000 | G22: 7850 | H22: =G22*Meta!$C$5/1000 -> 76.982202 | J22: 0.3 | K22: 400 | M22: CONSTANT | N22: PENDING | O22: FALSE | P22: KS D 3504 철근 콘크리트용 봉강 | Q22: SRC-KS-D3504 | R22: fy는 강종 기호의 공칭 항복강도. fu/연신율은 KS 원문 및 지름 조건 확인.
A23: REBAR-SD500 | B23: Reinforcing Steel | C23: SD500 | D23: SD500 reinforcing bar | F23: 200000 | G23: 7850 | H23: =G23*Meta!$C$5/1000 -> 76.982202 | J23: 0.3 | K23: 500 | M23: CONSTANT | N23: PENDING | O23: FALSE | P23: KS D 3504 철근 콘크리트용 봉강 | Q23: SRC-KS-D3504 | R23: fy는 강종 기호의 공칭 항복강도. fu/연신율은 KS 원문 및 지름 조건 확인.
A24: REBAR-SD600 | B24: Reinforcing Steel | C24: SD600 | D24: SD600 reinforcing bar | F24: 200000 | G24: 7850 | H24: =G24*Meta!$C$5/1000 -> 76.982202 | J24: 0.3 | K24: 600 | M24: CONSTANT | N24: PENDING | O24: FALSE | P24: KS D 3504 철근 콘크리트용 봉강 | Q24: SRC-KS-D3504 | R24: fy는 강종 기호의 공칭 항복강도. fu/연신율은 KS 원문 및 지름 조건 확인.
A25: REBAR-SD400S | B25: Reinforcing Steel | C25: SD400S | D25: SD400S reinforcing bar | F25: 200000 | G25: 7850 | H25: =G25*Meta!$C$5/1000 -> 76.982202 | J25: 0.3 | K25: 400 | M25: CONSTANT | N25: PENDING | O25: FALSE | P25: KS D 3504 철근 콘크리트용 봉강 | Q25: SRC-KS-D3504 | R25: fy는 강종 기호의 공칭 항복강도. fu/연신율은 KS 원문 및 지름 조건 확인.
A26: REBAR-SD500S | B26: Reinforcing Steel | C26: SD500S | D26: SD500S reinforcing bar | F26: 200000 | G26: 7850 | H26: =G26*Meta!$C$5/1000 -> 76.982202 | J26: 0.3 | K26: 500 | M26: CONSTANT | N26: PENDING | O26: FALSE | P26: KS D 3504 철근 콘크리트용 봉강 | Q26: SRC-KS-D3504 | R26: fy는 강종 기호의 공칭 항복강도. fu/연신율은 KS 원문 및 지름 조건 확인.
A27: REBAR-SD600S | B27: Reinforcing Steel | C27: SD600S | D27: SD600S reinforcing bar | F27: 200000 | G27: 7850 | H27: =G27*Meta!$C$5/1000 -> 76.982202 | J27: 0.3 | K27: 600 | M27: CONSTANT | N27: PENDING | O27: FALSE | P27: KS D 3504 철근 콘크리트용 봉강 | Q27: SRC-KS-D3504 | R27: fy는 강종 기호의 공칭 항복강도. fu/연신율은 KS 원문 및 지름 조건 확인.
A28: AL-6061-T6 | B28: Aluminum | C28: 6061-T6 | D28: Aluminum 6061-T6 | F28: 69000 | G28: 2700 | H28: =G28*Meta!$C$5/1000 -> 26.477955 | J28: 0.33 | M28: CONSTANT | N28: PENDING | O28: FALSE | P28: Extruded alloy technical data / alloy datasheets | Q28: SRC-HYDRO-AL | R28: 제품형태·두께·조질 세부조건별 강도 확인 필요.
A29: AL-6063-T6 | B29: Aluminum | C29: 6063-T6 | D29: Aluminum 6063-T6 | F29: 69000 | G29: 2700 | H29: =G29*Meta!$C$5/1000 -> 26.477955 | J29: 0.33 | M29: CONSTANT | N29: PENDING | O29: FALSE | P29: Extruded alloy technical data / alloy datasheets | Q29: SRC-HYDRO-AL | R29: 제품형태·두께·조질 세부조건별 강도 확인 필요.
A30: AL-6082-T6 | B30: Aluminum | C30: 6082-T6 | D30: Aluminum 6082-T6 | F30: 69000 | G30: 2700 | H30: =G30*Meta!$C$5/1000 -> 26.477955 | J30: 0.33 | M30: CONSTANT | N30: PENDING | O30: FALSE | P30: Extruded alloy technical data / alloy datasheets | Q30: SRC-HYDRO-AL | R30: 제품형태·두께·조질 세부조건별 강도 확인 필요.
A31: SS-304 | B31: Stainless Steel | C31: 304 | D31: Stainless steel 304 | F31: 200000 | G31: 7900 | H31: =G31*Meta!$C$5/1000 -> 77.472535 | J31: 0.3 | M31: CONSTANT | N31: PENDING | O31: FALSE | P31: Stainless steel grades / Prodec range datasheet | Q31: SRC-OUTOKUMPU | R31: 0.2% proof strength와 fu는 제품형태·가공상태·두께별 확인.
A32: SS-304L | B32: Stainless Steel | C32: 304L | D32: Stainless steel 304L | F32: 200000 | G32: 7900 | H32: =G32*Meta!$C$5/1000 -> 77.472535 | J32: 0.3 | M32: CONSTANT | N32: PENDING | O32: FALSE | P32: Stainless steel grades / Prodec range datasheet | Q32: SRC-OUTOKUMPU | R32: 0.2% proof strength와 fu는 제품형태·가공상태·두께별 확인.
A33: SS-316 | B33: Stainless Steel | C33: 316 | D33: Stainless steel 316 | F33: 200000 | G33: 8000 | H33: =G33*Meta!$C$5/1000 -> 78.4532 | J33: 0.3 | M33: CONSTANT | N33: PENDING | O33: FALSE | P33: Stainless steel grades / Prodec range datasheet | Q33: SRC-OUTOKUMPU | R33: 0.2% proof strength와 fu는 제품형태·가공상태·두께별 확인.
A34: SS-316L | B34: Stainless Steel | C34: 316L | D34: Stainless steel 316L | F34: 200000 | G34: 8000 | H34: =G34*Meta!$C$5/1000 -> 78.4532 | J34: 0.3 | M34: CONSTANT | N34: PENDING | O34: FALSE | P34: Stainless steel grades / Prodec range datasheet | Q34: SRC-OUTOKUMPU | R34: 0.2% proof strength와 fu는 제품형태·가공상태·두께별 확인.
A35: PS-WIRE | B35: Prestressing Steel | C35: PS Wire | D35: PS Wire | F35: 200000 | G35: 7850 | H35: =G35*Meta!$C$5/1000 -> 76.982202 | J35: 0.3 | M35: CONSTANT | N35: PENDING | O35: FALSE | P35: KS D 7002 PC 강선 및 PC 강연선 | Q35: SRC-KS-D7002 | R35: 공칭지름·종류별 인장강도 확인 필요; 프리스트레싱강은 fy 대신 proof stress 사용 가능.
A36: PS-BAR | B36: Prestressing Steel | C36: PS Bar | D36: PS Bar | F36: 200000 | G36: 7850 | H36: =G36*Meta!$C$5/1000 -> 76.982202 | J36: 0.3 | M36: CONSTANT | N36: PENDING | O36: FALSE | P36: PC 강봉 관련 KS | Q36: SRC-KS-PCBAR | R36: 공칭지름·종류별 인장강도 확인 필요; 프리스트레싱강은 fy 대신 proof stress 사용 가능.
A37: PS-STRAND | B37: Prestressing Steel | C37: PS Strand | D37: PS Strand | F37: 200000 | G37: 7850 | H37: =G37*Meta!$C$5/1000 -> 76.982202 | J37: 0.3 | M37: CONSTANT | N37: PENDING | O37: FALSE | P37: KS D 7002 PC 강선 및 PC 강연선 | Q37: SRC-KS-D7002 | R37: 공칭지름·종류별 인장강도 확인 필요; 프리스트레싱강은 fy 대신 proof stress 사용 가능.
A38: CABLE-STRUCTURAL-STRAND | B38: Cable | C38: Structural Strand | D38: Structural Strand | G38: 7850 | H38: =G38*Meta!$C$5/1000 -> 76.982202 | M38: CONSTANT | N38: PENDING | O38: FALSE | P38: 와이어로프 및 구조용 스트랜드 관련 KS | Q38: SRC-KS-CABLE | R38: 유효탄성계수·파단강도·질량은 구성 및 공칭지름별 제조사/KS 표 확인.
A39: CABLE-WIRE-ROPE-6X19 | B39: Cable | C39: Wire Rope 6x19 | D39: Wire Rope 6x19 | G39: 7850 | H39: =G39*Meta!$C$5/1000 -> 76.982202 | M39: CONSTANT | N39: PENDING | O39: FALSE | P39: 와이어로프 및 구조용 스트랜드 관련 KS | Q39: SRC-KS-CABLE | R39: 유효탄성계수·파단강도·질량은 구성 및 공칭지름별 제조사/KS 표 확인.
A40: CABLE-WIRE-ROPE-6X37 | B40: Cable | C40: Wire Rope 6x37 | D40: Wire Rope 6x37 | G40: 7850 | H40: =G40*Meta!$C$5/1000 -> 76.982202 | M40: CONSTANT | N40: PENDING | O40: FALSE | P40: 와이어로프 및 구조용 스트랜드 관련 KS | Q40: SRC-KS-CABLE | R40: 유효탄성계수·파단강도·질량은 구성 및 공칭지름별 제조사/KS 표 확인.
...

Sheet PropertyRules
A1: material_id | B1: property_name | C1: condition_type | D1: min_value | E1: min_inclusive | F1: max_value | G1: max_inclusive | H1: condition_unit | I1: product_form | J1: section_part | K1: property_value | L1: property_unit | M1: source_id | N1: note
A2: STL-SS275 | B2: fy_MPa | C2: thickness_range | D2: 0 | E2: FALSE | F2: 16 | G2: TRUE | H2: mm | K2: 275 | L2: MPa | M2: SRC-KS-D3503 | N2: 대표 두께구간. 경계 포함 방식과 제품형태를 KS 원문에서 확인.
A3: STL-SS275 | B3: fy_MPa | C3: thickness_range | D3: 16 | E3: FALSE | F3: 40 | G3: TRUE | H3: mm | L3: MPa | M3: SRC-KS-D3503 | N3: KS 원문 기계적 성질표 확인 후 입력.
A4: STL-SM355 | B4: fy_MPa | C4: thickness_range | D4: 0 | E4: FALSE | F4: 16 | G4: TRUE | H4: mm | L4: MPa | M4: SRC-KS-D3515 | N4: 두께별 KS 원문 기계적 성질표 확인 후 입력.
A5: STL-SM420 | B5: fy_MPa | C5: thickness_range | D5: 0 | E5: FALSE | F5: 16 | G5: TRUE | H5: mm | L5: MPa | M5: SRC-KS-D3515 | N5: 두께별 KS 원문 기계적 성질표 확인 후 입력.
A6: STL-SM460 | B6: fy_MPa | C6: thickness_range | D6: 0 | E6: FALSE | F6: 16 | G6: TRUE | H6: mm | L6: MPa | M6: SRC-KS-D3515 | N6: 두께별 KS 원문 기계적 성질표 확인 후 입력.
A7: MDF-GENERAL | B7: E_MPa | C7: thickness_range | D7: 10 | E7: FALSE | F7: 12 | G7: TRUE | H7: mm | K7: 2500 | L7: MPa | M7: SRC-EPF-MDF | N7: EN 13986 CE marking 예시의 두께별 최소/선언값.
A8: MDF-GENERAL | B8: E_MPa | C8: thickness_range | D8: 12 | E8: FALSE | F8: 19 | G8: TRUE | H8: mm | K8: 2200 | L8: MPa | M8: SRC-EPF-MDF | N8: EN 13986 CE marking 예시.
A9: MDF-GENERAL | B9: E_MPa | C9: thickness_range | D9: 19 | E9: FALSE | F9: 30 | G9: TRUE | H9: mm | K9: 2100 | L9: MPa | M9: SRC-EPF-MDF | N9: EN 13986 CE marking 예시.
A10: MDF-GENERAL | B10: E_MPa | C10: thickness_range | D10: 30 | E10: FALSE | F10: 45 | G10: TRUE | H10: mm | K10: 1900 | L10: MPa | M10: SRC-EPF-MDF | N10: EN 13986 CE marking 예시.
A11: MDF-GENERAL | B11: E_MPa | C11: thickness_range | D11: 45 | E11: FALSE | H11: mm | K11: 1700 | L11: MPa | M11: SRC-EPF-MDF | N11: 상한은 제품 범위에 따라 달라 제조사 확인.

Sheet Sections
A1: section_id | B1: category | C1: shape | D1: designation | E1: compatible_material_category | F1: dimensions | G1: area_mm2 | H1: Iy_mm4 | I1: Iz_mm4 | J1: J_mm4 | K1: property_source | L1: mass_per_length_kg_m | M1: unit_weight_per_length_kN_m | N1: source_id | O1: H_mm | P1: B_mm | Q1: tw_mm | R1: tf_mm | S1: b_mm2 | T1: h_mm3 | U1: t_mm | V1: D_mm | W1: d_mm4
A2: SEC-RECT-300X500 | B2: Solid | C2: Rectangle | D2: RECT-300x500 | E2: User Defined | F2: b=300; h=500 | G2: =S2*T2 -> 150000 | H2: =S2*POWER(T2,3)/12 -> 3125000000 | I2: =T2*POWER(S2,3)/12 -> 1125000000 | J2: =MAX(S2,T2)*POWER(MIN(S2,T2),3)*(1/3-0.21*MIN(S2,T2)/MAX(S2,T2)*(1-POWER(MIN(S2,T2),4)/(12*POWER(MAX(S2,T2),4)))) -> 2.8173708e+09 | K2: CALCULATED | N2: SRC-GEOMETRY | S2: 300 | T2: 500
A3: SEC-CIRC-D300 | B3: Solid | C3: Circle | D3: CIRCLE-D300 | E3: User Defined | F3: D=300 | G3: =PI()*POWER(V3,2)/4 -> 70685.835 | H3: =PI()*POWER(V3,4)/64 -> 3.9760782e+08 | I3: =PI()*POWER(V3,4)/64 -> 3.9760782e+08 | J3: =PI()*POWER(V3,4)/32 -> 7.9521564e+08 | K3: CALCULATED | N3: SRC-GEOMETRY | V3: 300
A4: SEC-H-300X300X10X15 | B4: Rolled Steel | C4: H/I Section | D4: H-300x300x10x15 | E4: Structural Steel | F4: H=300; B=300; tw=10; tf=15 | G4: =P4*R4*2+Q4*(O4-2*R4) -> 11700 | H4: =(P4*POWER(O4,3)-(P4-Q4)*POWER(O4-2*R4,3))/12 -> 199327500 | I4: =(2*R4*POWER(P4,3)+(O4-2*R4)*POWER(Q4,3))/12 -> 67522500 | J4: =(2*P4*POWER(R4,3)+(O4-2*R4)*POWER(Q4,3))/3 -> 765000 | K4: CALCULATED | L4: 91.845 | M4: =L4*Meta!$C$5/1000 -> 0.90069177 | N4: SRC-KS-D3502 | O4: 300 | P4: 300 | Q4: 10 | R4: 15
A5: SEC-C-200X80X7.5X11 | B5: Rolled Steel | C5: Channel | D5: C-200x80x7.5x11 | E5: Structural Steel | F5: H=200; B=80; tw=7.5; tf=11 | G5: =P5*R5*2+Q5*(O5-2*R5) -> 3095 | J5: =(2*P5*POWER(R5,3)+(O5-2*R5)*POWER(Q5,3))/3 -> 96017.917 | K5: CALCULATED | L5: 24.29575 | M5: =L5*Meta!$C$5/1000 -> 0.23825992 | N5: SRC-KS-D3502 | O5: 200 | P5: 80 | Q5: 7.5 | R5: 11
A6: SEC-L-100X100X10 | B6: Rolled Steel | C6: Angle | D6: L-100x100x10 | E6: Structural Steel | F6: b=100; h=100; t=10 | G6: =U6*(S6+T6-U6) -> 1900 | J6: =U6*POWER(S6,3)/3+U6*POWER(T6-U6,3)/3 -> 5763333.3 | K6: CALCULATED | L6: 14.915 | M6: =L6*Meta!$C$5/1000 -> 0.14626618 | N6: SRC-KS-D3502 | S6: 100 | T6: 100 | U6: 10
A7: SEC-BOX-200X200X9 | B7: Hollow | C7: Box | D7: BOX-200x200x9 | E7: Structural Steel | F7: b=200; h=200; t=9 | G7: =S7*T7-(S7-2*U7)*(T7-2*U7) -> 6876 | H7: =(S7*POWER(T7,3)-(S7-2*U7)*POWER(T7-2*U7,3))/12 -> 41900052 | I7: =(T7*POWER(S7,3)-(T7-2*U7)*POWER(S7-2*U7,3))/12 -> 41900052 | J7: =2*U7*POWER((S7-U7)*(T7-U7),2)/(S7+T7-2*U7) -> 62710839 | K7: CALCULATED | L7: 53.9766 | M7: =L7*Meta!$C$5/1000 -> 0.52932962 | N7: SRC-GEOMETRY | S7: 200 | T7: 200 | U7: 9
A8: SEC-PIPE-114.3X6 | B8: Hollow | C8: Pipe | D8: PIPE-114.3x6 | E8: Structural Steel | F8: D=114.3; t=6 | G8: =PI()*(POWER(V8,2)-POWER(V8-2*U8,2))/4 -> 2041.4069 | H8: =PI()*(POWER(V8,4)-POWER(V8-2*U8,4))/64 -> 3002116 | I8: =PI()*(POWER(V8,4)-POWER(V8-2*U8,4))/64 -> 3002116 | J8: =PI()*(POWER(V8,4)-POWER(V8-2*U8,4))/32 -> 6004231.9 | K8: CALCULATED | L8: 16.025044 | M8: =L8*Meta!$C$5/1000 -> 0.157152 | N8: SRC-GEOMETRY | U8: 6 | V8: 114.3
A9: SEC-CABLE-D15.2 | B9: Cable | C9: Cable | D9: CABLE-D15.2 | E9: Cable | F9: D=15.2 (nominal envelope) | K9: STANDARD_TABLE | N9: SRC-KS-CABLE | V9: 15.2

Sheet RC_Sections
A1: section_id | B1: section_type | C1: member_type | D1: width_mm | E1: height_mm | F1: diameter_mm | G1: concrete_material_id | H1: rebar_material_id | I1: cover_mm | J1: longitudinal_bar_diameter | K1: longitudinal_bar_count | L1: stirrup_diameter | M1: stirrup_spacing | N1: note
A2: RC-RECT-300X500-C24-SD400 | B2: Rectangle | D2: 300 | E2: 500 | G2: CONC-C24 | H2: REBAR-SD400 | I2: 40 | J2: 20 | K2: 4 | L2: 10 | M2: 200 | N2: 예시 조합. 배근·피복은 프로젝트 설계값이며 설계기준 검토 필요.
A3: RC-CIRC-D500-C30-SD400 | B3: Circle | F3: 500 | G3: CONC-C30 | H3: REBAR-SD400 | I3: 40 | J3: 20 | K3: 8 | L3: 10 | M3: 200 | N3: 예시 조합. 원형 띠철근 상세 및 최소피복 검토 필요.
A4: RC-USER | B4: User Defined | G4: USER-DEFINED | H4: USER-DEFINED | N4: 사용자 정의 RC 단면.

Sheet Sources
A1: source_id | B1: organization | C1: standard_or_document | D1: edition | E1: table_or_section | F1: description | G1: reference
A2: SRC-KDS-CONC | B2: 국가건설기준센터/국토교통부 | C2: KDS 14 20 10 콘크리트구조 해석과 설계 원칙 | D2: 2024 계열(적용 전 최신본 확인) | E2: 재료 물성 | F2: 콘크리트 탄성계수 공식 및 구조용 콘크리트 재료 규정. Δf 구간은 적용 프로젝트 기준 최신본 대조 필요. | G2: https://kcsc.re.kr/
A3: SRC-KDS-STEEL | B3: 국가건설기준센터/국토교통부 | C3: KDS 41 10 15 건축구조기준 설계하중 및 재료 상수 관련 기준 | D3: 현행본 확인 | E3: 강재 재료 상수 | F3: 강재 탄성계수·푸아송비 등 공통 설계 상수. 실제 적용 전 현행 기준 대조. | G3: https://kcsc.re.kr/
A4: SRC-KS-D3503 | B4: 국가기술표준원 | C4: KS D 3503 일반 구조용 압연 강재 | D4: 최종개정확인 2026-06-30 | E4: 종류·기계적 성질 | F4: SS275 적용 범위 및 두께별 기계적 성질의 기준 문서. 원문 표 확인이 필요한 셀은 VERIFY. | G4: https://www.standard.go.kr/KSCI/standardIntro/getStandardSearchView.do?ksNo=KSD3503&tmprKsNo=KSD3503
A5: SRC-KS-D3515 | B5: 국가기술표준원 | C5: KS D 3515 용접 구조용 압연 강재 | D5: 최종개정확인 2023-06-16 | E5: 종류·기계적 성질 | F5: SM 계열 강재의 적용 범위와 두께별 물성 기준. | G5: https://www.standard.go.kr/KSCI/standardIntro/getStandardSearchView.do?ksNo=KSD3515&tmprKsNo=KSD3515
A6: SRC-KS-SN | B6: 국가기술표준원 | C6: 건축구조용 압연강재 관련 KS | D6: 현행본 확인 | E6: 종류·기계적 성질 | F6: SN275/SN355/SN460의 정확한 KS 번호와 두께별 표를 프로젝트 적용 전 확인. | G6: https://www.standard.go.kr/
A7: SRC-KS-D3504 | B7: 국가기술표준원 | C7: KS D 3504 철근 콘크리트용 봉강 | D7: 최종개정확인 2025-06-02 | E7: 종류·기계적 성질 | F7: SD 계열 철근의 종류와 기계적 성질. | G7: https://standard.go.kr/KSCI/standardIntro/getStandardSearchView.do?ksNo=KSD3504&tmprKsNo=KSD3504
A8: SRC-HYDRO-AL | B8: Hydro | C8: Extruded alloy technical data / alloy datasheets | D8: 웹 자료(접속일 2026-08-12) | E8: 6061/6063/6082 | F8: 합금·질별 기계적 성질은 제품형태와 두께에 따라 달라짐. 확인된 공통 물리상수만 기입하고 강도는 VERIFY. | G8: https://www.hydro.com/en/global/aluminium/products/extruded-profiles/alloy-selection/
A9: SRC-OUTOKUMPU | B9: Outokumpu | C9: Stainless steel grades / Prodec range datasheet | D9: 웹 자료(접속일 2026-08-12) | E9: 304/304L/316/316L | F9: 제품형태·가공상태별 항복·인장강도 표. grade-only 행은 강도 VERIFY. | G9: https://www.outokumpu.com/en/products/product-ranges/prodec
A10: SRC-KS-D7002 | B10: 국가기술표준원 | C10: KS D 7002 PC 강선 및 PC 강연선 | D10: 최종개정확인 2024-09-13 | E10: 종류·치수·기계적 성질 | F10: PC 강선 및 강연선. 호칭/종별로 강도가 달라 grade-only 행은 VERIFY. | G10: https://www.standard.go.kr/KSCI/standardIntro/getStandardSearchView.do?ksNo=KSD7002&tmprKsNo=KSD7002
A11: SRC-KS-PCBAR | B11: 국가기술표준원 | C11: PC 강봉 관련 KS | D11: 현행본 확인 | E11: 종류·기계적 성질 | F11: PS Bar의 정확한 제품 규격·등급 확인 필요. | G11: https://www.standard.go.kr/
A12: SRC-KS-CABLE | B12: 국가기술표준원 | C12: 와이어로프 및 구조용 스트랜드 관련 KS | D12: 현행본 확인 | E12: 종류·치수·최소파단하중 | F12: 구성·공칭지름·소선 강도에 따라 물성이 달라 대표 grade-only 행은 VERIFY. | G12: https://www.standard.go.kr/
... A15: SRC-GEOMETRY | B15: OpenFrame Studio | C15: 기하 공식 | D15: 1.0 | E15: 단면적·단면2차모멘트·비틀림상수 | F15: 이상화된 날카로운 모서리 단면의 치수 기반 수식. 필렛/모서리 반경은 제외하므로 제조 표와 차이가 날 수 있음. | G15: https://en.wikipedia.org/wiki/List_of_second_moments_of_area
A16: SRC-USER | B16: 사용자 | C16: 사용자 정의 | D16: N/A | E16: N/A | F16: 사용자가 프로젝트별 검증값을 입력하는 행.

Sheet Validation
A1: check_id | B1: check_type | C1: target_sheet | D1: target_id | E1: result | F1: message | G1: checked_at
A2: VAL-001 | B2: DUPLICATE_ID | C2: Materials | D2: * | E2: PASS | F2: material_id 중복 없음 | G2: 46246
A3: VAL-002 | B3: DUPLICATE_ID | C3: Sections | D3: * | E3: PASS | F3: section_id 중복 없음 | G3: 46246
A4: VAL-003 | B4: DUPLICATE_ID | C4: RC_Sections | D4: * | E4: PASS | F4: section_id 중복 없음 | G4: 46246
A5: VAL-004 | B5: NUMERIC_TYPE | C5: All | D5: * | E5: PASS | F5: 숫자형 열에 문자열 없음 | G5: 46246
A6: VAL-005 | B6: SOURCE_REFERENCE | C6: All | D6: * | E6: PASS | F6: 모든 source_id 참조 유효 | G6: 46246
A7: VAL-006 | B7: CONDITIONAL_RULE | C7: Materials | D7: * | E7: PASS | F7: 모든 CONDITIONAL 재료에 숫자 property_value 규칙 존재 | G7: 46246
A8: VAL-007 | B8: RULE_OVERLAP | C8: PropertyRules | D8: * | E8: PASS | F8: 동일 조건 그룹 내 범위 중복 없음 | G8: 46246
A9: VAL-008 | B9: PHYSICAL_RANGE | C9: Materials/Sections | D9: * | E9: PASS | F9: 음수/비정상 물성치 없음 | G9: 46246
A10: VAL-009 | B10: LENGTH_UNIT_CONVERSION | C10: Sections | D10: * | E10: PASS | F10: kg/m → kN/m 변환식 일치 | G10: 46246
A11: VAL-010 | B11: DATA_PRESERVATION | C11: All | D11: * | E11: PASS | F11: 원본 행 보존: Materials 43, Rules 10, Sections 8, RC 3, Sources 15 | G11: 46246
A12: VAL-011 | B12: PENDING_STATUS | C12: Materials | D12: * | E12: NOTICE | F12: 31개 재료가 미검증 상태(PENDING/auto_apply=FALSE) | G12: 46246

Sheet Meta
A1: meta_group | B1: key | C1: value | D1: description
A2: DATABASE | B2: DATABASE_NAME | C2: OpenFrame Material & Section DB | D2: 데이터베이스 명
A3: DATABASE | B3: DATABASE_VERSION | C3: 0.1 | D3: 스키마 버전
A4: DATABASE | B4: UNIT_SYSTEM | C4: SI | D4: 단위계
A5: DATABASE | B5: GRAVITY | C5: 9.80665 | D5: m/s²
A6: DATABASE | B6: STATUS | C6: DEVELOPMENT | D6: 개발 상태
A7: DATABASE | B7: UPDATED | C7: 46246 | D7: 마지막 수정일
A8: PROPERTY_TYPE | B8: PROPERTY_TYPE | C8: CONSTANT | D8: 허용 enum
A9: PROPERTY_TYPE | B9: PROPERTY_TYPE | C9: FORMULA | D9: 허용 enum
A10: PROPERTY_TYPE | B10: PROPERTY_TYPE | C10: CONDITIONAL | D10: 허용 enum
A11: PROPERTY_TYPE | B11: PROPERTY_TYPE | C11: USER_DEFINED | D11: 허용 enum
A12: DATA_STATUS | B12: DATA_STATUS | C12: VERIFIED | D12: 허용 enum
A13: DATA_STATUS | B13: DATA_STATUS | C13: PENDING | D13: 허용 enum
A14: DATA_STATUS | B14: DATA_STATUS | C14: USER_DEFINED | D14: 허용 enum
